Workbook

Sheet xác định KMP
A5: A | B5: Mã Bravo | C5: Chi phí tiện ích chung
A6: 1 | B6: CP03-01 | C6: Điện | D6: CP Đích danh
A7: 2 | B7: CP03-02 | C7: Điện thoại bàn | D7: CP Phân bổ
A8: 3 | B8: CP03-03 | C8: Điện thoại di động | D8: CP Đích danh
A9: 4 | B9: CP03-04 | C9: Internet | D9: CP Phân bổ
A10: 5 | B10: CP03-05 | C10: Nước sinh hoạt | D10: CP Phân bổ
A11: 6 | B11: CP03-06 | C11: Nước uống | D11: CP Phân bổ
A12: 7 | B12: CP03-07 | C12: Chi phí xử lý chất thải (nước thải, rác, phí vệ sinh) | D12: CP Phân bổ
A13: 8 | B13: CP03-09 | C13: Xăng, dầu dùng cho quản lí văn phòng (xăng xe, nhiên liệu) | D13: CP Phân bổ
A14: 9 | B14: CP03-10 | C14: Phí môi trường (chăm sóc cây xanh, thảm cỏ) | D14: CP Phân bổ
A15: B | C15: Chi phí tiện ích văn phòng
A16: 10 | B16: CP04-01 | C16: Bưu phẩm, chuyển phát nhanh | D16: CP Phân bổ
A17: 11 | B17: CP04-02 | C17: Chi phí Photocopy (sao y, dịch thuật...) | D17: CP Phân bổ
A18: 12 | B18: CP04-04 | C18: Văn phòng phẩm (VPP văn phòng, vệ sinh phẩm, hóa phẩm) | D18: CP Đích danh
A19: 13 | B19: CP04-05 | C19: Chi phí trang trí văn phòng, quầy lễ tân | D19: CP Phân bổ
A20: 14 | B20: CP04-07 | C20: Chi phí in ấn (bao thư, namecard) | D20: CP Đích danh
A21: C | C21: Công tác phí
A22: 15 | B22: CP08-02 | C22: Chi phí khách sạn | D22: CP Đích danh
A23: 16 | B23: CP08-03 | C23: Chi phí vé máy bay, tàu xe, vé cầu đường | D23: CP Đích danh
A24: 17 | B24: CP08-04 | C24: Phụ cấp công tác phí (không bao gồm nhiên liệu) | D24: CP Đích danh
A25: D | C25: Hội họp và giao tế
A26: 18 | B26: CP09-02 | C26: Chi phí hội nghị (sơ kết, tổng kết) | D26: CP Phân bổ
A27: 19 | B27: CP09-04 | C27: Chi phí quà tặng cho mục đích giao tế (Không bao gồm chi phí tiếp khách phục vụ hoạt động KD) | D27: CP Phân bổ
A28: 20 | B28: CP04-06 | C28: Chi phí họp nội bộ, chi phí huấn luyện , tự đào tạo | D28: CP Phân bổ
A29: 21 | B29: CP08-01 | C29: Chi phí tiếp khách (bao gồm chi phí phòng chờ phục khách hàng trong Sr) | D29: CP Phân bổ
A30: E | C30: Chi phí quản lý tài sản
A31: 22 | B31: CP04-03 | C31: Công cụ dụng cụ (mua sắm bàn ghế, máy tính văn phòng…) | D31: CP Phân bổ
A32: 23 | B32: CP01 -22 | C32: Sữa chữa, bảo dưỡng TTB,CCDC HC | D32: CP Phân bổ
A33: F | C33: Hành chính nhân viên
A34: 24 | B34: CP02-04 | C34: Tiền cơm, tiền ăn | D34: CP Đích danh
A35: 25 | B35: CP03-08 | C35: Gas (phục vụ bếp ăn, nấu nướng) | D35: CP Phân bổ
A36: 26 | B36: CP02-15 | C36: Chi phí khám sức khỏe định kỳ | D36: CP Phân bổ
A37: 27 | B37: CP02-09 | C37: Đồng phục, bảo hộ LĐ | D37: CP Phân bổ
A38: G | C38: Chi phí thuê ngoài
A39: 28 | B39: CP07-04 | C39: Thuê xe (Không bao gồm CP thuê xe Demo) | D39: CP Phân bổ
A40: 29 | B40: CP07-01 | C40: Thuê khác (không bao gồm chi phí thuê văn phòng) | D40: CP Phân bổ

Sheet KMP
A1: Nội dung khoản mục chi phí hành chính
A2: STT | B2: Khoản mục | C2: Tên Khoản mục | D2: Diễn giải khoản mục
A3: I | C3: Chi phí tiện ích chung
A4: 1 | B4: CP03-01 | C4: Điện | D4: - Ghi nhận toàn bộ các khoản chi phí sử dụng điện căn cứ theo hóa đơn của Cty Điện Lực - Phân bổ chi tiết cho bộ phận, phòng ban sử dụng - Trích trước chi phí tiền điện trong trường hợp hóa đơn về sau.
A5: 2 | B5: CP03-02 | C5: Điện thoại bàn | D5: - Ghi nhận toàn bộ các khoản chi phí sử dụng điện thoại bàn căn cứ theo hóa đơn của nhà cung cấp - Phân bổ chi tiết cho bộ phận, phòng ban sử dụng - Trích trước chi phí tiền điện trong trường hợp hóa đơn về sau.
A6: 3 | B6: CP03-03 | C6: Điện thoại di động | D6: Căn cứ theo danh sách nhân sự được hỗ trợ chi phí điện thoại di dộng theo tháng. Căn cứ vào định mức thực tế được công ty hỗ trợ cho nhân sự từng vị trí: Trường hợp chi phí sử dụng thực tế > định mức hỗ trợ: lấy số định mức hỗ trợ, truy thu phần chi phí sử dụng vượt định mức. Trường hợp chi phí sử dụng thực tế < định mức hỗ trợ: lấy số chi phí sử dụng thực tế. Trường hợp định mức Thanh toán theo thực tế: lấy số chi phí sử dụng thực tế. Sim Hotline: định mức 200,000đ/tháng/sim, giao cụ thể 01 cá nhân quản lý, nếu chi phí sử dụng thực tế > định mức hỗ trợ: lấy số định mức hỗ trợ, truy thu phần chi phí sử dụng vượt định mức vào cá nhân quản lý. - Phân bổ chi tiết cho bộ phận, phòng ban sử dụng 'Lưu ý: Không hạch toán CP ĐTDĐ vào khoản mục CP02-13: Chi phí khác cho người lao động
A7: 4 | B7: CP03-04 | C7: Internet | D7: - Ghi nhận chi phí sử dụng Internet của đơn vị có phát sinh: + Chi phí sử dụng Internet + Cước truyển hình Cáp - Phân bổ chi tiết cho bộ phận, phòng ban sử dụng
A8: 5 | B8: CP03-05 | C8: Nước sinh hoạt | D8: - Ghi nhận các khoản chi phí sử dụng nước sinh hoạt, căn cứ theo chỉ số nước và hóa đơn của nhà cung cấp - Phân bổ chi tiết cho bộ phận, phòng ban sử dụng Lưu ý: Không đưa chi phí nước uống của CBCNV và nước chai Phục vụ khách hàng, hội họp vào CP 03-05
A9: 6 | B9: CP03-06 | C9: Nước uống | D9: - Ghi nhận các khoản chi phí sử dụng thức uống phục vụ cho nhu cầu làm việc của nhân viên gồm: Nước Bình, nước Chai (không phục vụ cho đào tạo, hội thao, hội nghị) - Phân bổ chi tiết cho bộ phận, phòng ban sử dụng Lưu ý: Chi phí nước chai tiếp khách đưa vào Khoản mục CP08-01: Chi phí tiếp khách.
A10: 7 | B10: CP03-07 | C10: Chi phí xử lý chất thải (nước thải, rác), phí vệ sinh | D10: - Ghi nhận các khoản chi phí xử lý chất thải sinh hoạt hàng tháng; - Phí xử lý chất thải nguy hại; xử lý nước thải công nghiệp. - Phí vệ sinh văn phòng, nhà xưởng, sân vườn; phí quét rác, lau chùi vệ sinh khuôn viên, nhà cửa. - Phí vệ sinh môi trường, Phí tài nguyên nước '- Không ghi nhận chi phí liên quan đến cây xanh trồng trên đất. - Giấy, nước rửa tay trong nhà vệ sinh đưa vào CP0 - Chi phí xử lý nhớt thải phân bổ vào KMP Chi phí khác của kinh doanh phục vụ
A11: 8 | B11: CP03-09 | C11: Xăng, dầu dùng cho quản lí văn phòng | D11: "- Ghi nhận vào KMP này các khoản như: + Chi phí xăng dầu xe công xa. + Nhiên liệu máy phát điện, máy cắt cỏ + Chi phí hỗ trợ xăng xe gắn máy cho CBCNV đi thị trường hội họp, đào tạo, huấn luyện, sơ kết, tổng kết. 'Lưu ý : + Chi phí xăng dầu hỗ trợ cho nhân viên đi thị trường đưa vào CP08- Chi phí công tác + Các chi phí xăng dầu sau không đưa vào CP03-09: - CP xăng dầu testdrive: Khoản mục CP 09-20: Chi phí lái thử xe - CP xăng dầu giao xe khách hàng: Khoản mục CP12-03: Chi phí giao hàng (vận chuyển, xăng , dầu …) hoặc Khoản mục - CP09-03: Chi phí khuyến mãi, quà tặng cho mục đích bán hàng. - CP xăng dầu ĐKĐK: Khoản mục CP12-02: Chi phí dịch vụ ra số. - CP xăng dầu xe trưng bày: Khoản mục CP12-07: Phí bảo quản xe trưng bày. - CP xăng dầu phát sinh khi sửa chữa lưu động: Khỏan mục CP05-01: Chi phí nguyên vật liệu ( dùng cho sản xuất) hoặc CP05-02: Chi phí nhiên liệu ( xăng, dầu, nhớt…dùng sản xuất)."
A12: 9 | B12: CP03-10 | C12: Phí môi trường (chăm sóc cây xanh, thảm cỏ) | D12: Ghi nhận các chi phí phát sinh bao gồm: - Chi phí hợp đồng cắt tỉa cây (thuê dịch vụ cắt tỉa cây, thuê nhân công cắt tỉa cây). - Chi phí thuê/mua, chăm sóc cây xanh, thảm cỏ xung quanh Sr. - Chi phí mua phân, thuốc bảo vệ thực vật,…. - Chi phí thuê máy cắt cỏ, xăng dầu dùng cho máy cắt cỏ. - Chi phí quan trắc môi trường. - Chi phí hút bể phốt. '-Chi phí thuê/mua cây xanh không trồng trên đất dùng để trưng bày trong văn phòng và các khoản chi phí chăm sóc các loại cây xanh này đưa vào Khoản mục CP04-05 Chi phí trang trí văn phòng, trang trí Quầy lễ tân
A13: II | C13: Chi phí tiện ích văn phòng
A14: 10 | B14: CP04-01 | C14: Bưu phẩm, chuyển phát nhanh | D14: - Ghi nhận các chi phí liên quan đến bưu phẩm, chuyển phát nhanh, chuyển thư : + Bao gồm: Gửi thư, tài liệu, hồ sơ, bưu kiện, gửi thư chiến dịch CSKH. - Hạch toán phân bổ cho từng BP sử dụng riêng Chi phí gửi thư chiến dịch CSKH dịch vụ--> Chi phí tổ chức sự kiện CP09-06
A15: 11 | B15: CP04-02 | C15: Chi phí Photocopy (sao y, dịch thuật...) | D15: - Chi phí dịch vụ photocopy tài liệu và dịch thuật mua ngoài. - Phí và lệ phí công chứng đưa vào khoản mục phí CP06- Phí và lệ phí
A16: 12 | B16: CP04-04 | C16: Văn phòng phẩm | D16: Văn phòng phẩm: giấy, bút, sổ tay cấp phát cho CB-NV,Chi phí làm Con dấu…
A17: 13 | B17: CP04-12 | C17: Tạp phẩm, hóa phẩm văn phòng | D17: Hóa phẩm vệ sinh, nước rửa tay, giấy VS, xịt khử mùi, hóa phẩm máy chà sàn,…
A18: 14 | B18: CP04-05 | C18: Chi phí trang trí văn phòng, quầy lễ tân | D18: "+ Chi phí mua hoa quầy lễ tân, hoa phòng chờ, cây thông noel, mai, đào tết... + Chi phí thuê, mua cây xanh trưng bày văn phòng + Chi phí chăm sóc cây xanh trưng bày văn phòng, hành lang, lối đi bao gồm: Phí cắt tỉa cây xanh, phân bón, thuốc trừ sâu cây xanh...E64 Lưu ý: CP hoa phục vụ testdrive: Khoản mục CP09-20: Chi phí lái thử xe. - Cây xanh hành lang, lối đi được trồng và chăm sóc trên đất đưa vào CP03-10 - Khuôn viên cây xanh, thảm cỏ
A19: 15 | B19: CP04-07 | C19: Chi phí in ấn (bao thư, namecard) | D19: - Bao gồm: + Chi phí liên quan đến bình mực cho máy in các loại, máy photo, máy fax,...bao gồm: mua mới, bơm mực, thay thế/sửa chữa: drum (trống), trục cao su, gạt mực,… + In namecard, In hóa đơn, bao thư, giấy ra cổng, sổ sách cho bảo vệ, lái xe,... + In băng rôn tuyển dụng, hiến máu, các bảng biển marketing khẩu hiệu.... + Chi phí thay thế , sửa chữa trục cao su ,gạt mực đơn vị đang cho vào CP10- Sửa chữa công cụ dụng cụ văn phòng & CP01-20 - Sửa chữa bảo trì TSCĐ (thiết bị dụng cụ quản lý) + In thẻ bảng tên CBCNV: đưa vào KMP CP02-09: đồng phục + BHLĐ + In băng rôn chương trình bán hàng, CSKH: Khoản mục: CP09-09: chi phí quảng cáo + In thư ngỏ, báo giá, catalogue,...: Khoản mục: CP09-08: Quảng cáo in ấn phẩm (catalogue, thư ngỏ, báo giá)
A20: 16 | B20: CP04-08 | C20: Chi phí hoạt động thư viện (sách, báo, …) | D20: - Chi phí báo chí cho BLĐ đơn vị, báo chí dùng chung & báo/tạp chí cho khách hàng, phòng chờ hàng ngày/tuần/tháng/quí.
A21: III | C21: Chi phí công tác
A22: 17 | B22: CP08-02 | C22: Chi phí khách sạn | D22: + Chi phí khách sạn, nhà nghỉ trong thời gian CBCNV đi công tác không phục vụ hoạt động giao xe, dịch vụ ra số, đào tạo huấn luyện, hội thao, hội nghị mang tính phúc lợi cho nhân viên như: hội họp, sơ kết, Tổng kết.... + CP khách sạn phát sinh khi sửa chữa lưu động. 'Chi phí khách sạn phát sinh khi giao xe: Khoản mục CP12-03: Chi phí giao hàng ( vận chuyển, xăng , dầu …) Chi phí khách sạn phát sinh khi ĐKĐK: Khoản mục CP12-02: Chi phí dịch vụ ra số
A23: 18 | B23: CP08-03 | C23: Chi phí vé máy bay, tàu xe, vé cầu đường | D23: Bao gồm: + Chi phí của CBCNV khi đi thị trường, hội họp, sơ kết, tổng kết bao gồm: + Chi phí vé máy bay, vé tàu, vé xe. + Chi phí vé cầu đường. + Chi phí taxi, xe ôm, xe buýt. + Chi phí taxi kế toán đi ngân hàng.. - Nắm rõ quy định của Cty về cấp bậc nhân sự được sử dụng phương tiện khi đi công tác tương ứng. - Nắm rõ giá vé đi lại từng loại phương tiện tại địa phương và từ địa phương đi/về Tp.HCM. Lưu ý danh sách CB biệt phái để lập chi phí tầu xe, máy bay về phép vào dịp Tết. Căn cứ chỉ tiêu kinh doanh bán hàng, họp để lập kế hoạch vé máy bay, cầu đường. Lưu ý: Chi phí vé máy bay, tàu xe, vé cầu đường phát sinh khi giao xe: Khoản mục CP12-03: Chi phí giao hàng ( vận chuyển, xăng , dầu …). CP vé máy bay, tàu, xe, vé cầu đường phát sinh khi ĐKĐK: Khoản mục CP12-02: Chi phí dịch vụ ra số. CP vé máy bay, tàu, xe, vé cầu đường phát sinh khi tham gia/ tố chức sự kiện: hạch toán vào Chi phí tổ chức sự kiện ( CP09-06). CP vé máy bay, cầu đường, tàu, xe phục vụ việc đào tạo, huấn luyện, hội thao, hội diễn mang tính phúc lợi cho cá nhân đưa vào CP02
A24: 19 | B24: CP08-04 | C24: Phụ cấp công tác phí | D24: Bao gồm: + Tiền cơm của CBCNV đi thị trường, hội họp, sơ kết, tổng kết. + Chi phí sinh hoạt phí khi đi thị trường, hội họp, sơ kết, tổng kết + Phụ cấp công tác phí phát sinh khi sửa chữa lưu động. + Chi phí xăng dầu hỗ trợ nhân viên đi thị trường trong trong trường hợp không dùng xe công vụ. - Phụ cấp công tác phí khi giao xe: Khoản mục CP12-03: Chi phí giao hàng (vận chuyển, xăng , dầu …). Phụ cấp công tác phí khi ĐKĐK: Khoản mục CP12-02: Chi phí dịch vụ ra số Tất cả các chi phí ăn uống, lưu trú và đi lại cho nhân sự đi tham gia/ tổ chức sự kiện đều hạch toán vào Chi phí tổ chức sự kiện ( CP09-06), định mức tùy vào tờ trình đươc duyệt ( nếu có) hoặc định mức công tác phí hiện hành
A25: IV | C25: Hội họp và giao tế | D25: #N/A
A26: 20 | B26: CP04-06 | C26: Chi phí họp nội bộ | D26: "- Bao gồm các chi phí liên quan đến công tác hậu cần phục vụ họp giao ban, đánh giá nhân sự: + In báo cáo; In bảng tên phuc vụ hội họp, hoa tươi + Chi phí thức uống (ngoài nước bình, nước đóng chai) như: Nước ngọt, café, nước ép... + Chi phí thực phẩm phục vụ hội họp: Bánh ngọt, trái cây.... + In ấn, tài liệu giáo án + Ăn uống (kể cả ăn ngoài giờ), teadresk, hoa tươi + Thuê máy chiếu, máy phát điện dự phòng, thuê bàn ghế, thuê giảng viên bên ngoài... + Thuê hội trường, thuê trang thiết bị bàn ghế phục vụ đào tạo"
A27: 21 | B27: CP04-11 | C27: Chi phí hội nghị sơ kết, tổng kết | D27: Các chi phí tổ chức hội nghị sơ kết, tổng kết: Dịch vụ tổ chức; trang trí, chuẩn bị địa điểm, phòng họp; Đồ dùng, thực phẩm phục vụ hội nghị
A28: 22 | B28: CP08-01 | C28: Tiếp khách mua xe/ bảo hiểm/ CQBN | D28: + Chi phí tiếp khách là cơ quan ban ngành (Bảo hiểm, ngân hàng,....) của các bộ phận nhằm tạo mối quan hệ + Chi phí tiếp khách là các cơ quan ban ngành (tiếp CSGT, ĐKĐK...)phục vụ bán xe của Bp Kinh doanh + Chi phí tiếp khách hàng mua xe, tiếp khách dịch vụ Lưu ý: + Chi phí mua hoa tặng khách tại lễ bàn giao xe của BP kinh doanh: Khoản mục CP12-03: Chi phí giao hàng '- Trường hợp đơn vị tiếp khách phục vụ bán hàng cho hoạt động xưởng không ghi nhận vào chi phí 627 mà chỉ được sử dụng chi phí 64* tương ứng
A29: 23 | B29: CP08-06 | C29: Tiếp khách phòng chờ | D29: Chi phí phòng chờ: nước chai, cafe, sữa, đường, bánh kẹo, trái cây,…
A30: 24 | B30: CP09-21 | C30: Chi phí quà tặng cho mục đích giao tế | D30: Chi phí quà tặng giao tế phục vụ cho mục đích ngoại giao: Công an, Quản lý thị trường, PCCC…
A31: V | C31: Chi phí quản lý tài sản
A32: 25 | B32: CP04-03 | C32: Công cụ dụng cụ văn phòng | D32: - Chi phí mua sắm công cụ dụng cụ và tài sản văn phòng, bao gồm công cụ dụng cụ thuê ngoài (hệ thống hoạt động độc lập, phân biệt với các CP sửa chữa trên): + Trang thiết bị văn phòng: bàn ghế; trang thiết bi CNTT, điện thoại bàn,… - Xuất kho CCDC ra sử dụng. Sử dụng mã TOL và TOS + Cần phân biệt với các chi phí sửa chữa CCDC ở KMP CP 01-22 - Sửa chữa, bảo trì CCDC
A33: 26 | B33: CP01-22 | C33: Sửa chữa, bảo trì thiết bị, CCDC | D33: - Ghi nhận các chi phí liên quan đến việc sửa chữa, bảo trì thiết bị CCDC tại văn phòng, xưởng sản xuất, công trường ( không Ghi nhận chi phí xây dựng cơ bản, chi phí nâng cấp công cụ dụng cụ, chi phí công cụ dụng cụ tiện ích sử dụng cho văn phòng) - xuất vật tư, CCDC phục vụ việc sửa chữa, bảo trì CCDC định kỳ Lưu ý: Đưa vào Mã Prel vs Pres
A34: 27 | B34: CP12-04 | C34: Chi phí xét xe, đăng kiểm xe công | D34: * Chi phí xét xe, đăng kiểm định ký của xe công. Lưu ý: Không hoạch toán phí đăng ký đăng kiểm xe công vào CP12-02 phí dịch vụ ra số
A35: 28 | B35: CP01-29 | C35: Khấu hao xe công | D35: - Khấu hao Xe công thuộc sở hữu của đơn vị
A36: VI | C36: Chi phí thuê ngoài
A37: 29 | B37: CP07-04 | C37: Thuê xe công | D37: "- Ghi nhận các chi phí thuê xe gồm: + Thuê xe công (Đối với việc thuê xe đưa đón CBNV đi làm hằng ngày thì ghi nhận vào CP02) + Thuê xe tập trung tham dự sơ kết, tổng kết KV & công ty '- Chi phí thuê xe cho các sự kiện: 8/3, hội thao, hội diễn mang tính phúc lợi cho nhân viên đưa vào CP02-03 -Chi phí thuê xe testdrive sử dụng khoản mục CP09-20: Chi phí lái thử xe, thuê xe trưng bày sử dụng khoản mục CP09-06: Chi phí tổ chức sự kiện (triễn lãm, hội chợ, roadshow)"
A38: 30 | B38: CP07-13 | C38: Thuê nhà công vụ | D38: + Chi phí thuê nhà công vụ: Là các chi phí phát sinh đến việc thuê nhà cho cán bộ có trách nhiệm đặc thù để ở, tiếp khách hoặc thực hiện các chức năng khác (Không bao gồm chi phí khách sạn cho cán bộ đi công tác) Lưu ý: Đối với chi phí thuê nhà tập thể cho cán bộ nhân viên ghi nhận vào CP02

Sheet KH CPHC 2026
A1: THACO AUTO Đồng Tháp Tổng CPHC
E2: Thực hiện 2025 | V2: KẾ HOẠCH QUÝ 1 NĂM 2026
C3: QIV | D3: Cả năm | E3: T1 | F3: T2 | G3: T3 | H3: QI | I3: T4 | J3: T5 | K3: T6 | L3: QII | M3: T7 | N3: T8 | O3: T9 | P3: QIII | Q3: T10 | R3: T11 | S3: T12 | T3: QIV | U3: Cả năm | V3: T1 | W3: T2 | X3: T3 | Y3: QI
A4: 1 | B4: Chi phí tiện ích chung | C4: 938.50707 | D4: 4260.3877 | E4: 325.11719 | F4: 298.112 | G4: 286.41563 | H4: 909.64482 | I4: 303.17621 | J4: 280.55977 | K4: 405.32442 | L4: 989.0604 | M4: 482.29416 | N4: 504.08671 | O4: ='QTCP Mỹ Tho'!E3+'QTCP Bến Tre'!E3+'QTCP Cao Lãnh'!E3+'QTCP Trà Vinh'!E3 -> 402.31084 | P4: =SUM(M4:O4) -> 1388.6917 | Q4: ='QTCP Mỹ Tho'!G3+'QTCP Bến Tre'!G3+'QTCP Cao Lãnh'!G3+'QTCP Trà Vinh'!G3 -> 370.13474 | R4: ='QTCP Mỹ Tho'!H3+'QTCP Bến Tre'!H3+'QTCP Cao Lãnh'!H3+'QTCP Trà Vinh'!H3 -> 373.54353 | S4: ='QTCP Mỹ Tho'!I3+'QTCP Bến Tre'!I3+'QTCP Cao Lãnh'!I3+'QTCP Trà Vinh'!I3 -> 389.90611 | T4: =SUM(Q4:S4) -> 1133.5844 | U4: =T4+P4+L4+H4 -> 4420.9813 | V4: ='QTCP Mỹ Tho'!L3+'QTCP Bến Tre'!L3+'QTCP Cao Lãnh'!L3+'QTCP Trà Vinh'!L3 -> 340.11363 | W4: ='QTCP Mỹ Tho'!M3+'QTCP Bến Tre'!M3+'QTCP Cao Lãnh'!M3+'QTCP Trà Vinh'!M3 -> 303.74972 | X4: ='QTCP Mỹ Tho'!N3+'QTCP Bến Tre'!N3+'QTCP Cao Lãnh'!N3+'QTCP Trà Vinh'!N3 -> 370.53815 | Y4: =SUM(V4:X4) -> 1014.4015
A5: 2 | B5: Chi phí tiện ích văn phòng | C5: 227.77132 | D5: 971.2537 | E5: 111.06993 | F5: 80.861302 | G5: 78.291855 | H5: 270.22309 | I5: 67.693609 | J5: 72.275747 | K5: 79.376307 | L5: 219.34566 | M5: 79.858641 | N5: 80.756828 | O5: ='QTCP Mỹ Tho'!E157+'QTCP Bến Tre'!E94+'QTCP Cao Lãnh'!E67+'QTCP Trà Vinh'!E94 -> 66.798322 | P5: =SUM(M5:O5) -> 227.41379 | Q5: ='QTCP Mỹ Tho'!G157+'QTCP Bến Tre'!G94+'QTCP Cao Lãnh'!G67+'QTCP Trà Vinh'!G94 -> 71.507481 | R5: ='QTCP Mỹ Tho'!H157+'QTCP Bến Tre'!H94+'QTCP Cao Lãnh'!H67+'QTCP Trà Vinh'!H94 -> 89.229706 | S5: ='QTCP Mỹ Tho'!I157+'QTCP Bến Tre'!I94+'QTCP Cao Lãnh'!I67+'QTCP Trà Vinh'!I94 -> 80.292551 | T5: =SUM(Q5:S5) -> 241.02974 | U5: =T5+P5+L5+H5 -> 958.01228 | V5: ='QTCP Mỹ Tho'!L157+'QTCP Bến Tre'!L94+'QTCP Cao Lãnh'!L67+'QTCP Trà Vinh'!L94 -> 61.655605 | W5: ='QTCP Mỹ Tho'!M157+'QTCP Bến Tre'!M94+'QTCP Cao Lãnh'!M67+'QTCP Trà Vinh'!M94 -> 58.752237 | X5: ='QTCP Mỹ Tho'!N157+'QTCP Bến Tre'!N94+'QTCP Cao Lãnh'!N67+'QTCP Trà Vinh'!N94 -> 57.454027 | Y5: =SUM(V5:X5) -> 177.86187
A6: 3 | B6: Chi phí công tác | C6: 77.521803 | D6: 391.46583 | E6: 20.259131 | F6: 20.706155 | G6: 33.196174 | H6: 74.16146 | I6: 24.260092 | J6: 16.167532 | K6: 24.75622 | L6: 65.183844 | M6: 26.216412 | N6: 19.942511 | O6: ='QTCP Mỹ Tho'!E277+'QTCP Bến Tre'!E165+'QTCP Cao Lãnh'!E117+'QTCP Trà Vinh'!E165 -> 17.296158 | P6: =SUM(M6:O6) -> 63.45508 | Q6: ='QTCP Mỹ Tho'!G277+'QTCP Bến Tre'!G165+'QTCP Cao Lãnh'!G117+'QTCP Trà Vinh'!G165 -> 22.389025 | R6: ='QTCP Mỹ Tho'!H277+'QTCP Bến Tre'!H165+'QTCP Cao Lãnh'!H117+'QTCP Trà Vinh'!H165 -> 25.118 | S6: ='QTCP Mỹ Tho'!I277+'QTCP Bến Tre'!I165+'QTCP Cao Lãnh'!I117+'QTCP Trà Vinh'!I165 -> 24.648194 | T6: =SUM(Q6:S6) -> 72.155219 | U6: =T6+P6+L6+H6 -> 274.9556 | V6: ='QTCP Mỹ Tho'!L277+'QTCP Bến Tre'!L165+'QTCP Cao Lãnh'!L117+'QTCP Trà Vinh'!L165 -> 12.944415 | W6: ='QTCP Mỹ Tho'!M277+'QTCP Bến Tre'!M165+'QTCP Cao Lãnh'!M117+'QTCP Trà Vinh'!M165 -> 10.743613 | X6: ='QTCP Mỹ Tho'!N277+'QTCP Bến Tre'!N165+'QTCP Cao Lãnh'!N117+'QTCP Trà Vinh'!N165 -> 15.218859 | Y6: =SUM(V6:X6) -> 38.906887
A7: 4 | B7: Hội họp và giao tế | C7: 171.69104 | D7: 705.6148 | E7: 124.54598 | F7: 47.364849 | G7: 87.338501 | H7: 259.24933 | I7: 47.608283 | J7: 49.493845 | K7: 58.687126 | L7: 155.78925 | M7: 69.531715 | N7: 46.39463 | O7: ='QTCP Mỹ Tho'!E329+'QTCP Bến Tre'!E196+'QTCP Cao Lãnh'!E139+'QTCP Trà Vinh'!E196 -> 61.736715 | P7: =SUM(M7:O7) -> 177.66306 | Q7: ='QTCP Mỹ Tho'!G329+'QTCP Bến Tre'!G196+'QTCP Cao Lãnh'!G139+'QTCP Trà Vinh'!G196 -> 56.142024 | R7: ='QTCP Mỹ Tho'!H329+'QTCP Bến Tre'!H196+'QTCP Cao Lãnh'!H139+'QTCP Trà Vinh'!H196 -> 48.759831 | S7: ='QTCP Mỹ Tho'!I329+'QTCP Bến Tre'!I196+'QTCP Cao Lãnh'!I139+'QTCP Trà Vinh'!I196 -> 47.921822 | T7: =SUM(Q7:S7) -> 152.82368 | U7: =T7+P7+L7+H7 -> 745.52532 | V7: ='QTCP Mỹ Tho'!L329+'QTCP Bến Tre'!L196+'QTCP Cao Lãnh'!L139+'QTCP Trà Vinh'!L196 -> 70.382677 | W7: ='QTCP Mỹ Tho'!M329+'QTCP Bến Tre'!M196+'QTCP Cao Lãnh'!M139+'QTCP Trà Vinh'!M196 -> 49.865438 | X7: ='QTCP Mỹ Tho'!N329+'QTCP Bến Tre'!N196+'QTCP Cao Lãnh'!N139+'QTCP Trà Vinh'!N196 -> 80.353284 | Y7: =SUM(V7:X7) -> 200.6014
A8: 5 | B8: Chi phí quản lý tài sản | C8: 573.32709 | D8: 2460.1683 | E8: 188.78858 | F8: 187.79054 | G8: 187.4437 | H8: 564.02283 | I8: 167.95022 | J8: 163.32496 | K8: 148.12339 | L8: 479.39857 | M8: 151.37592 | N8: 174.44028 | O8: ='QTCP Mỹ Tho'!E415+'QTCP Bến Tre'!E247+'QTCP Cao Lãnh'!E175+'QTCP Trà Vinh'!E247 -> 147.94072 | P8: =SUM(M8:O8) -> 473.75692 | Q8: ='QTCP Mỹ Tho'!G415+'QTCP Bến Tre'!G247+'QTCP Cao Lãnh'!G175+'QTCP Trà Vinh'!G247 -> 151.06454 | R8: ='QTCP Mỹ Tho'!H415+'QTCP Bến Tre'!H247+'QTCP Cao Lãnh'!H175+'QTCP Trà Vinh'!H247 -> 130.53079 | S8: ='QTCP Mỹ Tho'!I415+'QTCP Bến Tre'!I247+'QTCP Cao Lãnh'!I175+'QTCP Trà Vinh'!I247 -> 145.40439 | T8: =SUM(Q8:S8) -> 426.99971 | U8: =T8+P8+L8+H8 -> 1944.178 | V8: ='QTCP Mỹ Tho'!L415+'QTCP Bến Tre'!L247+'QTCP Cao Lãnh'!L175+'QTCP Trà Vinh'!L247 -> 118.65588 | W8: ='QTCP Mỹ Tho'!M415+'QTCP Bến Tre'!M247+'QTCP Cao Lãnh'!M175+'QTCP Trà Vinh'!M247 -> 114.22453 | X8: ='QTCP Mỹ Tho'!N415+'QTCP Bến Tre'!N247+'QTCP Cao Lãnh'!N175+'QTCP Trà Vinh'!N247 -> 117.62189 | Y8: =SUM(V8:X8) -> 350.5023
A9: 6 | B9: Chi phí thuê ngoài | C9: 40.884833 | D9: 380.51851 | E9: 30.937633 | F9: 30.801133 | G9: 29.6113 | H9: 91.350067 | I9: 30.8423 | J9: 29.5868 | K9: 30.8543 | L9: 91.2834 | M9: 30.8543 | N9: 30.8578 | O9: ='QTCP Mỹ Tho'!E484+'QTCP Bến Tre'!E288+'QTCP Cao Lãnh'!E204+'QTCP Trà Vinh'!E288 -> 30.8298 | P9: =SUM(M9:O9) -> 92.5419 | Q9: ='QTCP Mỹ Tho'!G484+'QTCP Bến Tre'!G288+'QTCP Cao Lãnh'!G204+'QTCP Trà Vinh'!G288 -> 30.99 | R9: ='QTCP Mỹ Tho'!H484+'QTCP Bến Tre'!H288+'QTCP Cao Lãnh'!H204+'QTCP Trà Vinh'!H288 -> 26.786 | S9: ='QTCP Mỹ Tho'!I484+'QTCP Bến Tre'!I288+'QTCP Cao Lãnh'!I204+'QTCP Trà Vinh'!I288 -> 26.658 | T9: =SUM(Q9:S9) -> 84.434 | U9: =T9+P9+L9+H9 -> 359.60937 | V9: ='QTCP Mỹ Tho'!L484+'QTCP Bến Tre'!L288+'QTCP Cao Lãnh'!L204+'QTCP Trà Vinh'!L288 -> 23.944 | W9: ='QTCP Mỹ Tho'!M484+'QTCP Bến Tre'!M288+'QTCP Cao Lãnh'!M204+'QTCP Trà Vinh'!M288 -> 23.944 | X9: ='QTCP Mỹ Tho'!N484+'QTCP Bến Tre'!N288+'QTCP Cao Lãnh'!N204+'QTCP Trà Vinh'!N288 -> 23.896 | Y9: =SUM(V9:X9) -> 71.784
A10: TỔNG | C10: =SUM(C4:C9) -> 2029.7032 | D10: =SUM(D4:D9) -> 9169.4089 | E10: =SUM(E4:E9) -> 800.71845 | F10: =SUM(F4:F9) -> 665.63598 | G10: =SUM(G4:G9) -> 702.29716 | H10: =SUM(H4:H9) -> 2168.6516 | I10: =SUM(I4:I9) -> 641.53072 | J10: =SUM(J4:J9) -> 611.40865 | ... Y10: =SUM(Y4:Y9) -> 1854.058
A11: Doanh thu | C11: 399675.93 | D11: 1271816.6 | E11: 67706.794 | F11: 80580.156 | G11: 109563.62 | H11: 263704.78 | I11: 110469.46 | J11: 108938.95 | K11: 140948.96 | L11: 359499.67 | M11: 98485.163 | N11: 94673.501 | O11: 105276.32 | P11: 356694.32 | Q11: 99168.36 | R11: 185397.96 | S11: 202459.21 | T11: 586676.33 | U11: 1566575.1
A12: Chi phí HC/ Doanh thu (%) | C12: =C10/C11 -> 0.0050783723 | D12: =D10/D11 -> 0.0072096943 | E12: =E10/E11 -> 0.011826264 | F12: =F10/F11 -> 0.0082605447 | G12: =G10/G11 -> 0.0064099484 | H12: =H10/H11 -> 0.0082237858 | I12: =I10/I11 -> 0.0058073128 | J12: =J10/J11 -> 0.0056123971 | ... Y12: =Y10/Y11 -> #DIV/0!
A13: Số lượng nhân sự | C13: 309 | D13: 309 | E13: 301 | F13: 300 | G13: 295 | H13: 295 | I13: 294 | J13: 291 | K13: 287 | L13: 287 | M13: 286 | N13: 284 | O13: 284 | P13: 284 | Q13: 266 | R13: 266 | S13: 266 | T13: 266 | U13: 266
A14: Chi phí HC/ Nhân sự (tr/đồng) | C14: =C10/C13/3 -> 2.1895395 | D14: =D10/D13/12 -> 2.4728719 | E14: =E10/E13 -> 2.6601942 | F14: =F10/F13 -> 2.2187866 | G14: =G10/G13 -> 2.3806683 | H14: =H10/H13/3 -> 2.4504538 | I14: =I10/I13 -> 2.1820773 | J14: =J10/J13 -> 2.1010607 | K14: =K10/K13 -> 2.6032117 | L14: =6.92252191986063/3 -> 2.3075073 | M14: 2.9230485 | N14: 2.9425417 | O14: 2.4948357 | P14: =8.33008282145329/3 -> 2.7766943 | Q14: 2.4915358 | R14: 2.4915358 | S14: 2.4915358 | T14: =7.47460748304498/3 -> 2.4915358 | U14: =30.1474471870819/12 -> 2.5122873
A15: Số lượng xe bán | C15: 572 | D15: 1814 | E15: 91 | F15: 129 | G15: 166 | H15: =SUM(E15:G15) -> 386 | I15: 162 | J15: 167 | K15: 179 | L15: =SUM(I15:K15) -> 508 | M15: 143 | N15: 149 | O15: 159 | P15: =SUM(M15:O15) -> 451 | Q15: 161 | R15: 272 | S15: 297 | T15: =SUM(Q15:S15) -> 730 | U15: =T15+P15+L15+H15 -> 2075

Sheet 1.Danh muc CPHC
A1: DANH MỤC CHI PHÍ HÀNH CHÍNH TẠI CTY TỈNH THÀNH | EK1: =40*26 -> 1040
A2: CÔNG TY THACO AUTO ĐỒNG THÁP | AO2: SHOWROOM MỸ THO | AT2: 2.4 | CC2: SHOWROOM CAI LẬY | DQ2: SHOWROOM BẾN TRE | FE2: SHOWROOM CAO LÃNH | GS2: SHOWROOM TRÀ VINH
BH3: Mỹ Tho | BK3: 0.3 | EJ3: Bến Tre | FX3: Cao Lãnh | HL3: Trà Vinh
A4: Stt | C4: Khoản mục phí | D4: Năm 2024 | F4: Thực hiện Năm 2025 | V4: Cả năm | W4: NĂM 2026 | AO4: Stt | AQ4: Khoản mục phí | AR4: Năm 2024 | AT4: Thực hiện Năm 2025 | BJ4: Cả năm | BK4: NĂM 2026 | CC4: Stt | CE4: Khoản mục phí | CF4: Năm 2024 | CH4: Thực hiện Năm 2025 | CX4: Cả năm | CY4: NĂM 2026 | DQ4: Stt | DS4: Khoản mục phí | DT4: Năm 2024 | DV4: Thực hiện Năm 2025 | EL4: Cả năm | EM4: NĂM 2026 | FE4: Stt | FG4: Khoản mục phí | FH4: Năm 2024 | FJ4: Thực hiện Năm 2025 | FZ4: Cả năm 2025 | GA4: NĂM 2026 | GS4: Stt | GU4: Khoản mục phí | GV4: Năm 2024 | GX4: Thực hiện Năm 2025 | HN4: Cả năm 2025 | HO4: NĂM 2026
D5: QIV | E5: Cả năm | F5: T1 | G5: T2 | H5: T3 | I5: Quý I | J5: T4 | K5: T5 | L5: T6 | M5: Quý II | N5: T7 | O5: T8 | P5: T9 | Q5: Quý III | R5: T10 | S5: T11 | T5: T12 | U5: Qúy IV | W5: T1 | X5: T2 | Y5: T3 | Z5: Qúy 1 | AA5: T4 | AB5: T5 | AC5: T6 | AD5: Qúy II | AE5: T7 | AF5: T8 | AG5: T9 | AH5: Qúy III | AI5: T10 | AJ5: T11 | AK5: T12 | AL5: Quý IV | AM5: Năm 2026 | AR5: QIV | AS5: Cả năm | AT5: T1 | AU5: T2 | AV5: T3 | AW5: Quý I | AX5: T4 | AY5: T5 | AZ5: T6 | BA5: Quý II | BB5: T7 | BC5: T8 | BD5: T9 | BE5: Quý III | BF5: T10 | BG5: T11 | BH5: T12 | BI5: Qúy IV | BK5: T1 | BL5: T2 | BM5: T3 | BN5: Qúy 1 | BO5: T4 | BP5: T5 | BQ5: T6 | BR5: Qúy II | BS5: T7 | BT5: T8 | BU5: T9 | BV5: Qúy III | BW5: T10 | BX5: T11 | BY5: T12 | BZ5: Quý IV | CA5: Năm 2026 | CF5: QIV | CG5: Cả năm | CH5: T1 | CI5: T2 | CJ5: T3 | CK5: Quý I | CL5: T4 | CM5: T5 | CN5: T6 | CO5: Quý II | CP5: T7 | CQ5: T8 | CR5: T9 | CS5: Quý III | CT5: T10 | CU5: T11 | CV5: T12 | CW5: Qúy IV | CY5: T1 | CZ5: T2 | DA5: T3 | DB5: Qúy 1 | DC5: T4 | DD5: T5 | DE5: T6 | DF5: Qúy II | DG5: T7 | DH5: T8 | DI5: T9 | DJ5: Qúy III | DK5: T10 | DL5: T11 | DM5: T12 | DN5: Quý IV | DO5: Năm 2026 | DT5: QIV | DU5: Cả năm | DV5: T1 | DW5: T2 | DX5: T3 | DY5: Quý I | DZ5: T4 | EA5: T5 | EB5: T6 | EC5: Quý II | ED5: T7 | EE5: T8 | EF5: T9 | EG5: Quý III | EH5: T10 | EI5: T11 | EJ5: T12 | EK5: Qúy IV | EM5: T1 | EN5: T2 | EO5: T3 | EP5: Qúy 1 | EQ5: T4 | ER5: T5 | ES5: T6 | ET5: Qúy II | EU5: T7 | EV5: T8 | EW5: T9 | EX5: Qúy III | EY5: T10 | EZ5: T11 | FA5: T12 | FB5: Quý IV | FC5: Năm 2026 | FH5: QIV | FI5: Cả năm | FJ5: T1 | FK5: T2 | FL5: T3 | FM5: Quý I | FN5: T4 | FO5: T5 | FP5: T6 | FQ5: Quý II | FR5: T7 | FS5: T8 | FT5: T9 | FU5: Quý III | FV5: T10 | FW5: T11 | FX5: T12 | FY5: Qúy IV | GA5: T1 | GB5: T2 | GC5: T3 | GD5: Qúy 1 | GE5: T4 | GF5: T5 | GG5: T6 | GH5: Qúy II | GI5: T7 | GJ5: T8 | GK5: T9 | GL5: Qúy III | GM5: T10 | GN5: T11 | GO5: T12 | GP5: Quý IV | GQ5: Năm 2026 | GV5: QIV | GW5: Cả năm | GX5: T1 | GY5: T2 | GZ5: T3 | HA5: Quý I | HB5: T4 | HC5: T5 | HD5: T6 | HE5: Quý II | HF5: T7 | HG5: T8 | HH5: T9 | HI5: Quý III | HJ5: T10 | HK5: T11 | HL5: T12 | HM5: Qúy IV | HO5: T1 | HP5: T2 | HQ5: T3 | HR5: Qúy 1 | HS5: T4 | HT5: T5 | HU5: T6 | HV5: Qúy II | HW5: T7 | HX5: T8 | HY5: T9 | HZ5: Qúy III | IA5: T10 | IB5: T11 | IC5: T12 | ID5: Quý IV | IE5: Năm 2026
C6: TỔNG CHI PHÍ | D6: =D7+D17+D25+D29+D35+D40 -> 2029.7032 | E6: =E7+E17+E25+E29+E35+E40 -> 9169.4089 | F6: =F7+F17+F25+F29+F35+F40 -> 800.71845 | G6: =G7+G17+G25+G29+G35+G40 -> 665.63598 | H6: =H7+H17+H25+H29+H35+H40 -> 702.29716 | I6: =I7+I17+I25+I29+I35+I40 -> 2168.6516 | J6: =J7+J17+J25+J29+J35+J40 -> 641.53072 | K6: =K7+K17+K25+K29+K35+K40 -> 611.40865 | ... AM6: =AM7+AM17+AM25+AM29+AM35+AM40 -> 208.53956 | AQ6: TỔNG CHI PHÍ | AR6: =AR7+AR17+AR25+AR29+AR35+AR40 -> 747.33089 | AS6: =AS7+AS17+AS25+AS29+AS35+AS40 -> 3494.878 | AT6: =AT7+AT17+AT25+AT29+AT35+AT40 -> 298.67444 | AU6: =AU7+AU17+AU25+AU29+AU35+AU40 -> 274.07063 | AV6: =AV7+AV17+AV25+AV29+AV35+AV40 -> 308.06608 | AW6: =AW7+AW17+AW25+AW29+AW35+AW40 -> 880.81115 | AX6: =AX7+AX17+AX25+AX29+AX35+AX40 -> 324.53435 | AY6: =AY7+AY17+AY25+AY29+AY35+AY40 -> 305.31667 | ... CA6: =CA7+CA17+CA25+CA29+CA35+CA40 -> 0 | CE6: TỔNG CHI PHÍ | CF6: =CF7+CF17+CF25+CF29+CF35+CF40 -> 139.02743 | CG6: =CG7+CG17+CG25+CG29+CG35+CG40 -> 1240.1713 | CH6: =CH7+CH17+CH25+CH29+CH35+CH40 -> 96.605263 | CI6: =CI7+CI17+CI25+CI29+CI35+CI40 -> 88.325222 | CJ6: =CJ7+CJ17+CJ25+CJ29+CJ35+CJ40 -> 89.918687 | CK6: =CK7+CK17+CK25+CK29+CK35+CK40 -> 274.84917 | CL6: =CL7+CL17+CL25+CL29+CL35+CL40 -> 0 | CM6: =CM7+CM17+CM25+CM29+CM35+CM40 -> 0 | ... CX6: =CX7+CX17+CX25+CX29+CX35+CX40 -> 274.84917 | DS6: TỔNG CHI PHÍ | DT6: =DT7+DT17+DT25+DT29+DT35+DT40 -> 385.84722 | DU6: =DU7+DU17+DU25+DU29+DU35+DU40 -> 1289.5166 | DV6: =DV7+DV17+DV25+DV29+DV35+DV40 -> 133.91551 | DW6: =DW7+DW17+DW25+DW29+DW35+DW40 -> 98.421609 | DX6: =DX7+DX17+DX25+DX29+DX35+DX40 -> 95.984577 | DY6: =DY7+DY17+DY25+DY29+DY35+DY40 -> 328.32169 | DZ6: =DZ7+DZ17+DZ25+DZ29+DZ35+DZ40 -> 101.2108 | EA6: =EA7+EA17+EA25+EA29+EA35+EA40 -> 95.081019 | ... EP6: =EP7+EP17+EP25+EP29+EP35+EP40 -> 0 | FG6: TỔNG CHI PHÍ | FH6: =FH7+FH17+FH25+FH29+FH35+FH40 -> 394.25866 | FI6: =FI7+FI17+FI25+FI29+FI35+FI40 -> 1552.7993 | FJ6: =FJ7+FJ17+FJ25+FJ29+FJ35+FJ40 -> 140.80361 | FK6: =FK7+FK17+FK25+FK29+FK35+FK40 -> 102.57564 | FL6: =FL7+FL17+FL25+FL29+FL35+FL40 -> 105.98736 | FM6: =FM7+FM17+FM25+FM29+FM35+FM40 -> 349.3666 | FN6: =FN7+FN17+FN25+FN29+FN35+FN40 -> 113.22422 | FO6: =FO7+FO17+FO25+FO29+FO35+FO40 -> 106.53659 | ... GQ6: =GQ7+GQ17+GQ25+GQ29+GQ35+GQ40 -> 0 | GU6: TỔNG CHI PHÍ | GV6: =GV7+GV17+GV25+GV29+GV35+GV40 -> 363.23896 | GW6: =GW7+GW17+GW25+GW29+GW35+GW40 -> 1592.0437 | GX6: =GX7+GX17+GX25+GX29+GX35+GX40 -> 130.71963 | GY6: =GY7+GY17+GY25+GY29+GY35+GY40 -> 102.24289 | GZ6: =GZ7+GZ17+GZ25+GZ29+GZ35+GZ40 -> 102.34046 | HA6: =HA7+HA17+HA25+HA29+HA35+HA40 -> 335.30297 | HB6: =HB7+HB17+HB25+HB29+HB35+HB40 -> 102.56135 | HC6: =HC7+HC17+HC25+HC29+HC35+HC40 -> 104.47437 | ... IE6: =IE7+IE17+IE25+IE29+IE35+IE40 -> 208.53956
A7: I | C7: Chi phí tiện ích chung | D7: =SUM(D8:D16) -> 938.50707 | E7: =SUM(E8:E16) -> 4260.3877 | F7: =SUM(F8:F16) -> 325.11719 | G7: =SUM(G8:G16) -> 298.112 | H7: =SUM(H8:H16) -> 286.41563 | I7: =SUM(I8:I16) -> 909.64482 | J7: =SUM(J8:J16) -> 303.17621 | K7: =SUM(K8:K16) -> 280.55977 | ... AM7: =SUM(AM8:AM16) -> 118.35201 | AO7: I | AQ7: Chi phí tiện ích chung | AR7: =SUM(AR8:AR16) -> 305.92806 | AS7: =SUM(AS8:AS16) -> 1479.0723 | AT7: =SUM(AT8:AT16) -> 102.87352 | AU7: =SUM(AU8:AU16) -> 96.759837 | AV7: =SUM(AV8:AV16) -> 94.158559 | AW7: =SUM(AW8:AW16) -> 293.79191 | AX7: =SUM(AX8:AX16) -> 138.0922 | AY7: =SUM(AY8:AY16) -> 109.73173 | ... CA7: =SUM(CA8:CA16) -> 0 | CC7: I | CE7: Chi phí tiện ích chung | CF7: =SUM(CF8:CF16) -> 84.458338 | CG7: =SUM(CG8:CG16) -> 608.99415 | CH7: =SUM(CH8:CH16) -> 55.121297 | CI7: =SUM(CI8:CI16) -> 49.564633 | CJ7: =SUM(CJ8:CJ16) -> 48.340655 | CK7: =SUM(CK8:CK16) -> 153.02659 | CL7: =SUM(CL8:CL16) -> 0 | CM7: =SUM(CM8:CM16) -> 0 | ... CX7: =SUM(CX8:CX16) -> 153.02659 | DQ7: I | DS7: Chi phí tiện ích chung | DT7: =SUM(DT8:DT16) -> 169.48105 | DU7: =SUM(DU8:DU16) -> 675.42354 | DV7: =SUM(DV8:DV16) -> 57.365208 | DW7: =SUM(DW8:DW16) -> 58.439497 | DX7: =SUM(DX8:DX16) -> 49.219859 | DY7: =SUM(DY8:DY16) -> 165.02456 | DZ7: =SUM(DZ8:DZ16) -> 56.614171 | EA7: =SUM(EA8:EA16) -> 57.210872 | ... EP7: =SUM(EP8:EP16) -> 0 | FE7: I | FG7: Chi phí tiện ích chung | FH7: =SUM(FH8:FH16) -> 196.13527 | FI7: =SUM(FI8:FI16) -> 773.4789 | FJ7: =SUM(FJ8:FJ16) -> 55.090629 | FK7: =SUM(FK8:FK16) -> 47.690844 | FL7: =SUM(FL8:FL16) -> 51.764505 | FM7: =SUM(FM8:FM16) -> 154.54598 | FN7: =SUM(FN8:FN16) -> 58.946909 | FO7: =SUM(FO8:FO16) -> 58.562779 | ... GQ7: =SUM(GQ8:GQ16) -> 0 | GS7: I | GU7: Chi phí tiện ích chung | GV7: =SUM(GV8:GV16) -> 182.50436 | GW7: =SUM(GW8:GW16) -> 723.41882 | GX7: =SUM(GX8:GX16) -> 54.666542 | GY7: =SUM(GY8:GY16) -> 45.657186 | GZ7: =SUM(GZ8:GZ16) -> 42.932049 | HA7: =SUM(HA8:HA16) -> 143.25578 | HB7: =SUM(HB8:HB16) -> 49.522935 | HC7: =SUM(HC8:HC16) -> 55.05439 | ... IE7: =SUM(IE8:IE16) -> 118.35201
A8: 1 | B8: CP03-01 | C8: Điện | D8: =D45+D82+D119+D156+D193 -> 619.97386 | E8: =E45+E82+E119+E156+E193 -> 2955.4415 | F8: =F45+F82+F119+F156+F193 -> 208.81697 | G8: =G45+G82+G119+G156+G193 -> 181.32705 | H8: =H45+H82+H119+H156+H193 -> 180.899 | I8: =I45+I82+I119+I156+I193 -> 571.04302 | J8: =J45+J82+J119+J156+J193 -> 185.12732 | K8: =K45+K82+K119+K156+K193 -> 174.62201 | ... AM8: =AM45+AM82+AM119+AM156+AM193 -> 84.633238 | AO8: 1 | AP8: CP03-01 | AQ8: Điện | AR8: =AR45+AR82+AR119+AR156+AR193 -> 169.80032 | AS8: =AS45+AS82+AS119+AS156+AS193 -> 937.53938 | AT8: =AT45+AT82+AT119+AT156+AT193 -> 50.082078 | AU8: =AU45+AU82+AU119+AU156+AU193 -> 48.292486 | AV8: =AV45+AV82+AV119+AV156+AV193 -> 39.555366 | AW8: =AW45+AW82+AW119+AW156+AW193 -> 137.92993 | AX8: =AX45+AX82+AX119+AX156+AX193 -> 63.991636 | AY8: =AY45+AY82+AY119+AY156+AY193 -> 43.57945 | ... CA8: =CA45+CA82+CA119+CA156+CA193 -> 0 | CC8: 1 | CD8: CP03-01 | CE8: Điện | CF8: ='1.Danh muc CPHC'!CF45+'1.Danh muc CPHC'!CF82+'1.Danh muc CPHC'!CF119+'1.Danh muc CPHC'!CF156+'1.Danh muc CPHC'!CF193 -> 67.241745 | CG8: ='1.Danh muc CPHC'!CG45+'1.Danh muc CPHC'!CG82+'1.Danh muc CPHC'!CG119+'1.Danh muc CPHC'!CG156+'1.Danh muc CPHC'!CG193 -> 476.76709 | CH8: ='1.Danh muc CPHC'!CH45+'1.Danh muc CPHC'!CH82+'1.Danh muc CPHC'!CH119+'1.Danh muc CPHC'!CH156+'1.Danh muc CPHC'!CH193 -> 44.933144 | CI8: ='1.Danh muc CPHC'!CI45+'1.Danh muc CPHC'!CI82+'1.Danh muc CPHC'!CI119+'1.Danh muc CPHC'!CI156+'1.Danh muc CPHC'!CI193 -> 38.503702 | CJ8: ='1.Danh muc CPHC'!CJ45+'1.Danh muc CPHC'!CJ82+'1.Danh muc CPHC'!CJ119+'1.Danh muc CPHC'!CJ156+'1.Danh muc CPHC'!CJ193 -> 35.938496 | CK8: ='1.Danh muc CPHC'!CK45+'1.Danh muc CPHC'!CK82+'1.Danh muc CPHC'!CK119+'1.Danh muc CPHC'!CK156+'1.Danh muc CPHC'!CK193 -> 119.37534 | CL8: =CL45+CL82+CL119+CL156+CL193 -> 0 | CM8: =CM45+CM82+CM119+CM156+CM193 -> 0 | CN8: =CN45+CN82+CN119+CN156+CN193 -> 0 | CO8: =CO45+CO82+CO119+CO156+CO193 -> 0 | CP8: =CP45+CP82+CP119+CP156+CP193 -> 0 | CQ8: =CQ45+CQ82+CQ119+CQ156+CQ193 -> 0 | CR8: =CR45+CR82+CR119+CR156+CR193 -> 0 | CS8: =CS45+CS82+CS119+CS156+CS193 -> 0 | ... CX8: =CX45+CX82+CX119+CX156+CX193 -> 119.37534 | DQ8: 1 | DR8: CP03-01 | DS8: Điện | DT8: =DT45+DT82+DT119+DT156+DT193 -> 137.56435 | DU8: =DU45+DU82+DU119+DU156+DU193 -> 554.82763 | DV8: =DV45+DV82+DV119+DV156+DV193 -> 44.882413 | DW8: =DW45+DW82+DW119+DW156+DW193 -> 39.936575 | DX8: =DX45+DX82+DX119+DX156+DX193 -> 40.462445 | DY8: =DY45+DY82+DY119+DY156+DY193 -> 125.28143 | DZ8: =DZ45+DZ82+DZ119+DZ156+DZ193 -> 46.590068 | EA8: =EA45+EA82+EA119+EA156+EA193 -> 46.315303 | ... EP8: =EP45+EP82+EP119+EP156+EP193 -> 0 | FE8: 1 | FF8: CP03-01 | FG8: Điện | FH8: =FH45+FH82+FH119+FH156+FH193 -> 131.56613 | FI8: =FI45+FI82+FI119+FI156+FI193 -> 531.45749 | FJ8: =FJ45+FJ82+FJ119+FJ156+FJ193 -> 38.845714 | FK8: =FK45+FK82+FK119+FK156+FK193 -> 29.702193 | FL8: =FL45+FL82+FL119+FL156+FL193 -> 37.201756 | FM8: =FM45+FM82+FM119+FM156+FM193 -> 105.74966 | FN8: =FN45+FN82+FN119+FN156+FN193 -> 42.595488 | FO8: =FO45+FO82+FO119+FO156+FO193 -> 44.275826 | ... GQ8: =GQ45+GQ82+GQ119+GQ156+GQ193 -> 0 | GS8: 1 | GT8: CP03-01 | GU8: Điện | GV8: =GV45+GV82+GV119+GV156+GV193 -> 113.80132 | GW8: =GW45+GW82+GW119+GW156+GW193 -> 454.84993 | GX8: =GX45+GX82+GX119+GX156+GX193 -> 30.073618 | GY8: =GY45+GY82+GY119+GY156+GY193 -> 24.892092 | GZ8: =GZ45+GZ82+GZ119+GZ156+GZ193 -> 27.740942 | HA8: =HA45+HA82+HA119+HA156+HA193 -> 82.706652 | HB8: =HB45+HB82+HB119+HB156+HB193 -> 31.950126 | HC8: =HC45+HC82+HC119+HC156+HC193 -> 40.451427 | ... IE8: =IE45+IE82+IE119+IE156+IE193 -> 84.633238
A9: 2 | B9: CP03-02 | C9: Điện thoại bàn | D9: =D46+D83+D120+D157+D194 -> 4.2422678 | E9: =E46+E83+E120+E157+E194 -> 17.158368 | F9: =F46+F83+F120+F157+F194 -> 1.5329232 | G9: =G46+G83+G120+G157+G194 -> 1.0781381 | H9: =H46+H83+H120+H157+H194 -> 1.0217536 | I9: =I46+I83+I120+I157+I194 -> 3.6328149 | J9: =J46+J83+J120+J157+J194 -> 1.024924 | K9: =K46+K83+K120+K157+K194 -> 1.064101 | ... AM9: =AM46+AM83+AM120+AM157+AM194 -> 0.806795 | AO9: 2 | AP9: CP03-02 | AQ9: Điện thoại bàn | AR9: =AR46+AR83+AR120+AR157+AR194 -> 1.8868144 | AS9: =AS46+AS83+AS120+AS157+AS194 -> 7.2416738 | AT9: =AT46+AT83+AT120+AT157+AT194 -> 0.62922376 | AU9: =AU46+AU83+AU120+AU157+AU194 -> 0.57373888 | AV9: =AV46+AV83+AV120+AV157+AV194 -> 0.63055344 | AW9: =AW46+AW83+AW120+AW157+AW194 -> 1.8335161 | AX9: =AX46+AX83+AX120+AX157+AX194 -> 0.861226 | AY9: =AY46+AY83+AY120+AY157+AY194 -> 0.898305 | ... CA9: =CA46+CA83+CA120+CA157+CA194 -> 0 | CC9: 2 | CD9: CP03-02 | CE9: Điện thoại bàn | CF9: ='1.Danh muc CPHC'!CF46+'1.Danh muc CPHC'!CF83+'1.Danh muc CPHC'!CF120+'1.Danh muc CPHC'!CF157+'1.Danh muc CPHC'!CF194 -> 0.3188736 | CG9: ='1.Danh muc CPHC'!CG46+'1.Danh muc CPHC'!CG83+'1.Danh muc CPHC'!CG120+'1.Danh muc CPHC'!CG157+'1.Danh muc CPHC'!CG194 -> 0.39428467 | CH9: ='1.Danh muc CPHC'!CH46+'1.Danh muc CPHC'!CH83+'1.Danh muc CPHC'!CH120+'1.Danh muc CPHC'!CH157+'1.Danh muc CPHC'!CH194 -> 0.27160648 | CI9: ='1.Danh muc CPHC'!CI46+'1.Danh muc CPHC'!CI83+'1.Danh muc CPHC'!CI120+'1.Danh muc CPHC'!CI157+'1.Danh muc CPHC'!CI194 -> 0.15647424 | CJ9: ='1.Danh muc CPHC'!CJ46+'1.Danh muc CPHC'!CJ83+'1.Danh muc CPHC'!CJ120+'1.Danh muc CPHC'!CJ157+'1.Danh muc CPHC'!CJ194 -> 0.17196912 | CK9: ='1.Danh muc CPHC'!CK46+'1.Danh muc CPHC'!CK83+'1.Danh muc CPHC'!CK120+'1.Danh muc CPHC'!CK157+'1.Danh muc CPHC'!CK194 -> 0.60004984 | CL9: =CL46+CL83+CL120+CL157+CL194 -> 0 | CM9: =CM46+CM83+CM120+CM157+CM194 -> 0 | CN9: =CN46+CN83+CN120+CN157+CN194 -> 0 | CO9: =CO46+CO83+CO120+CO157+CO194 -> 0 | CP9: =CP46+CP83+CP120+CP157+CP194 -> 0 | CQ9: =CQ46+CQ83+CQ120+CQ157+CQ194 -> 0 | CR9: =CR46+CR83+CR120+CR157+CR194 -> 0 | CS9: =CS46+CS83+CS120+CS157+CS194 -> 0 | ... CX9: =CX46+CX83+CX120+CX157+CX194 -> 0.60004984 | DQ9: 2 | DR9: CP03-02 | DS9: Điện thoại bàn | DT9: =DT46+DT83+DT120+DT157+DT194 -> 1.030029 | DU9: =DU46+DU83+DU120+DU157+DU194 -> 3.855311 | DV9: =DV46+DV83+DV120+DV157+DV194 -> 0.355055 | DW9: =DW46+DW83+DW120+DW157+DW194 -> 0.23722 | DX9: =DX46+DX83+DX120+DX157+DX194 -> 0.199231 | DY9: =DY46+DY83+DY120+DY157+DY194 -> 0.791506 | DZ9: =DZ46+DZ83+DZ120+DZ157+DZ194 -> 0.04909 | EA9: =EA46+EA83+EA120+EA157+EA194 -> 0.04909 | ... EP9: =EP46+EP83+EP120+EP157+EP194 -> 0 | FE9: 2 | FF9: CP03-02 | FG9: Điện thoại bàn | FH9: =FH46+FH83+FH120+FH157+FH194 -> 0.23526 | FI9: =FI46+FI83+FI120+FI157+FI194 -> 2.244521 | FJ9: =FJ46+FJ83+FJ120+FJ157+FJ194 -> 0.02 | FK9: =FK46+FK83+FK120+FK157+FK194 -> 0.02 | FL9: =FL46+FL83+FL120+FL157+FL194 -> 0.02 | FM9: =FM46+FM83+FM120+FM157+FM194 -> 0.06 | FN9: =FN46+FN83+FN120+FN157+FN194 -> 0.02 | FO9: =FO46+FO83+FO120+FO157+FO194 -> 0.02 | ... GQ9: =GQ46+GQ83+GQ120+GQ157+GQ194 -> 0 | GS9: 2 | GT9: CP03-02 | GU9: Điện thoại bàn | GV9: =GV46+GV83+GV120+GV157+GV194 -> 0.7712908 | GW9: =GW46+GW83+GW120+GW157+GW194 -> 3.422578 | GX9: =GX46+GX83+GX120+GX157+GX194 -> 0.257038 | GY9: =GY46+GY83+GY120+GY157+GY194 -> 0.090705 | GZ9: =GZ46+GZ83+GZ120+GZ157+GZ194 -> 0 | HA9: =HA46+HA83+HA120+HA157+HA194 -> 0.347743 | HB9: =HB46+HB83+HB120+HB157+HB194 -> 0.094608 | HC9: =HC46+HC83+HC120+HC157+HC194 -> 0.096706 | ... IE9: =IE46+IE83+IE120+IE157+IE194 -> 0.806795
A10: 3 | B10: CP03-03 | C10: Điện thoại di động | D10: =D47+D84+D121+D158+D195 -> 62.449585 | E10: =E47+E84+E121+E158+E195 -> 281.67957 | F10: =F47+F84+F121+F158+F195 -> 26.075856 | G10: =G47+G84+G121+G158+G195 -> 22.75078 | H10: =H47+H84+H121+H158+H195 -> 20.56366 | I10: =I47+I84+I121+I158+I195 -> 69.390295 | J10: =J47+J84+J121+J158+J195 -> 21.798916 | K10: =K47+K84+K121+K158+K195 -> 20.820964 | ... AM10: =AM47+AM84+AM121+AM158+AM195 -> 4.669388 | AO10: 3 | AP10: CP03-03 | AQ10: Điện thoại di động | AR10: =AR47+AR84+AR121+AR158+AR195 -> 23.281311 | AS10: =AS47+AS84+AS121+AS158+AS195 -> 111.82984 | AT10: =AT47+AT84+AT121+AT158+AT195 -> 11.255289 | AU10: =AU47+AU84+AU121+AU158+AU195 -> 9.3204692 | AV10: =AV47+AV84+AV121+AV158+AV195 -> 8.0974199 | AW10: =AW47+AW84+AW121+AW158+AW195 -> 28.673178 | AX10: =AX47+AX84+AX121+AX158+AX195 -> 10.161353 | AY10: =AY47+AY84+AY121+AY158+AY195 -> 9.701578 | ... CA10: =CA47+CA84+CA121+CA158+CA195 -> 0 | CC10: 3 | CD10: CP03-03 | CE10: Điện thoại di động | CF10: ='1.Danh muc CPHC'!CF47+'1.Danh muc CPHC'!CF84+'1.Danh muc CPHC'!CF121+'1.Danh muc CPHC'!CF158+'1.Danh muc CPHC'!CF195 -> 3.4085808 | CG10: ='1.Danh muc CPHC'!CG47+'1.Danh muc CPHC'!CG84+'1.Danh muc CPHC'!CG121+'1.Danh muc CPHC'!CG158+'1.Danh muc CPHC'!CG195 -> 30.191185 | CH10: ='1.Danh muc CPHC'!CH47+'1.Danh muc CPHC'!CH84+'1.Danh muc CPHC'!CH121+'1.Danh muc CPHC'!CH158+'1.Danh muc CPHC'!CH195 -> 2.0935112 | CI10: ='1.Danh muc CPHC'!CI47+'1.Danh muc CPHC'!CI84+'1.Danh muc CPHC'!CI121+'1.Danh muc CPHC'!CI158+'1.Danh muc CPHC'!CI195 -> 2.2855216 | CJ10: ='1.Danh muc CPHC'!CJ47+'1.Danh muc CPHC'!CJ84+'1.Danh muc CPHC'!CJ121+'1.Danh muc CPHC'!CJ158+'1.Danh muc CPHC'!CJ195 -> 2.0265028 | CK10: ='1.Danh muc CPHC'!CK47+'1.Danh muc CPHC'!CK84+'1.Danh muc CPHC'!CK121+'1.Danh muc CPHC'!CK158+'1.Danh muc CPHC'!CK195 -> 6.4055356 | CL10: =CL47+CL84+CL121+CL158+CL195 -> 0 | CM10: =CM47+CM84+CM121+CM158+CM195 -> 0 | CN10: =CN47+CN84+CN121+CN158+CN195 -> 0 | CO10: =CO47+CO84+CO121+CO158+CO195 -> 0 | CP10: =CP47+CP84+CP121+CP158+CP195 -> 0 | CQ10: =CQ47+CQ84+CQ121+CQ158+CQ195 -> 0 | CR10: =CR47+CR84+CR121+CR158+CR195 -> 0 | CS10: =CS47+CS84+CS121+CS158+CS195 -> 0 | ... CX10: =CX47+CX84+CX121+CX158+CX195 -> 6.4055356 | DQ10: 3 | DR10: CP03-03 | DS10: Điện thoại di động | DT10: =DT47+DT84+DT121+DT158+DT195 -> 10.311549 | DU10: =DU47+DU84+DU121+DU158+DU195 -> 36.015901 | DV10: =DV47+DV84+DV121+DV158+DV195 -> 5.030663 | DW10: =DW47+DW84+DW121+DW158+DW195 -> 3.235127 | DX10: =DX47+DX84+DX121+DX158+DX195 -> 3.192061 | DY10: =DY47+DY84+DY121+DY158+DY195 -> 11.457851 | DZ10: =DZ47+DZ84+DZ121+DZ158+DZ195 -> 3.154781 | EA10: =EA47+EA84+EA121+EA158+EA195 -> 2.953482 | ... EP10: =EP47+EP84+EP121+EP158+EP195 -> 0 | FE10: 3 | FF10: CP03-03 | FG10: Điện thoại di động | FH10: =FH47+FH84+FH121+FH158+FH195 -> 11.507845 | FI10: =FI47+FI84+FI121+FI158+FI195 -> 51.258972 | FJ10: =FJ47+FJ84+FJ121+FJ158+FJ195 -> 3.439006 | FK10: =FK47+FK84+FK121+FK158+FK195 -> 3.546874 | FL10: =FL47+FL84+FL121+FL158+FL195 -> 2.787168 | FM10: =FM47+FM84+FM121+FM158+FM195 -> 9.773048 | FN10: =FN47+FN84+FN121+FN158+FN195 -> 3.702353 | FO10: =FO47+FO84+FO121+FO158+FO195 -> 3.715255 | ... GQ10: =GQ47+GQ84+GQ121+GQ158+GQ195 -> 0 | GS10: 3 | GT10: CP03-03 | GU10: Điện thoại di động | GV10: =GV47+GV84+GV121+GV158+GV195 -> 13.940299 | GW10: =GW47+GW84+GW121+GW158+GW195 -> 52.383678 | GX10: =GX47+GX84+GX121+GX158+GX195 -> 4.257387 | GY10: =GY47+GY84+GY121+GY158+GY195 -> 4.362788 | GZ10: =GZ47+GZ84+GZ121+GZ158+GZ195 -> 4.460508 | HA10: =HA47+HA84+HA121+HA158+HA195 -> 13.080683 | HB10: =HB47+HB84+HB121+HB158+HB195 -> 4.780429 | HC10: =HC47+HC84+HC121+HC158+HC195 -> 4.450649 | ... IE10: =IE47+IE84+IE121+IE158+IE195 -> 4.669388
A11: 4 | B11: CP03-04 | C11: Internet | D11: =D48+D85+D122+D159+D196 -> 32.604906 | E11: =E48+E85+E122+E159+E196 -> 120.77338 | F11: =F48+F85+F122+F159+F196 -> 11.651901 | G11: =G48+G85+G122+G159+G196 -> 12.393059 | H11: =H48+H85+H122+H159+H196 -> 14.358759 | I11: =I48+I85+I122+I159+I196 -> 38.403719 | J11: =J48+J85+J122+J159+J196 -> 22.381484 | K11: =K48+K85+K122+K159+K196 -> 21.988371 | ... AM11: =AM48+AM85+AM122+AM159+AM196 -> 1.675908 | AO11: 4 | AP11: CP03-04 | AQ11: Internet | AR11: =AR48+AR85+AR122+AR159+AR196 -> 18.538396 | AS11: =AS48+AS85+AS122+AS159+AS196 -> 64.608724 | AT11: =AT48+AT85+AT122+AT159+AT196 -> 5.6306627 | AU11: =AU48+AU85+AU122+AU159+AU196 -> 6.3488602 | AV11: =AV48+AV85+AV122+AV159+AV196 -> 7.7850269 | AW11: =AW48+AW85+AW122+AW159+AW196 -> 19.76455 | AX11: =AX48+AX85+AX122+AX159+AX196 -> 17.479545 | AY11: =AY48+AY85+AY122+AY159+AY196 -> 15.947308 | ... CA11: =CA48+CA85+CA122+CA159+CA196 -> 0 | CC11: 4 | CD11: CP03-04 | CE11: Internet | CF11: ='1.Danh muc CPHC'!CF48+'1.Danh muc CPHC'!CF85+'1.Danh muc CPHC'!CF122+'1.Danh muc CPHC'!CF159+'1.Danh muc CPHC'!CF196 -> 2.6129046 | CG11: ='1.Danh muc CPHC'!CG48+'1.Danh muc CPHC'!CG85+'1.Danh muc CPHC'!CG122+'1.Danh muc CPHC'!CG159+'1.Danh muc CPHC'!CG196 -> 9.6 | CH11: ='1.Danh muc CPHC'!CH48+'1.Danh muc CPHC'!CH85+'1.Danh muc CPHC'!CH122+'1.Danh muc CPHC'!CH159+'1.Danh muc CPHC'!CH196 -> 1.4086725 | CI11: ='1.Danh muc CPHC'!CI48+'1.Danh muc CPHC'!CI85+'1.Danh muc CPHC'!CI122+'1.Danh muc CPHC'!CI159+'1.Danh muc CPHC'!CI196 -> 1.6170175 | CJ11: ='1.Danh muc CPHC'!CJ48+'1.Danh muc CPHC'!CJ85+'1.Danh muc CPHC'!CJ122+'1.Danh muc CPHC'!CJ159+'1.Danh muc CPHC'!CJ196 -> 2.0090363 | CK11: ='1.Danh muc CPHC'!CK48+'1.Danh muc CPHC'!CK85+'1.Danh muc CPHC'!CK122+'1.Danh muc CPHC'!CK159+'1.Danh muc CPHC'!CK196 -> 5.0347263 | CL11: =CL48+CL85+CL122+CL159+CL196 -> 0 | CM11: =CM48+CM85+CM122+CM159+CM196 -> 0 | CN11: =CN48+CN85+CN122+CN159+CN196 -> 0 | CO11: =CO48+CO85+CO122+CO159+CO196 -> 0 | CP11: =CP48+CP85+CP122+CP159+CP196 -> 0 | CQ11: =CQ48+CQ85+CQ122+CQ159+CQ196 -> 0 | CR11: =CR48+CR85+CR122+CR159+CR196 -> 0 | CS11: =CS48+CS85+CS122+CS159+CS196 -> 0 | ... CX11: =CX48+CX85+CX122+CX159+CX196 -> 5.0347263 | DQ11: 4 | DR11: CP03-04 | DS11: Internet | DT11: =DT48+DT85+DT122+DT159+DT196 -> 2.705727 | DU11: =DU48+DU85+DU122+DU159+DU196 -> 11.844532 | DV11: =DV48+DV85+DV122+DV159+DV196 -> 1.370151 | DW11: =DW48+DW85+DW122+DW159+DW196 -> 1.400818 | DX11: =DX48+DX85+DX122+DX159+DX196 -> 1.370151 | DY11: =DY48+DY85+DY122+DY159+DY196 -> 4.14112 | DZ11: =DZ48+DZ85+DZ122+DZ159+DZ196 -> 1.707394 | EA11: =EA48+EA85+EA122+EA159+EA196 -> 1.874699 | ... EP11: =EP48+EP85+EP122+EP159+EP196 -> 0 | FE11: 4 | FF11: CP03-04 | FG11: Internet | FH11: =FH48+FH85+FH122+FH159+FH196 -> 4.999092 | FI11: =FI48+FI85+FI122+FI159+FI196 -> 19.996368 | FJ11: =FJ48+FJ85+FJ122+FJ159+FJ196 -> 1.834546 | FK11: =FK48+FK85+FK122+FK159+FK196 -> 1.498182 | FL11: =FL48+FL85+FL122+FL159+FL196 -> 1.666364 | FM11: =FM48+FM85+FM122+FM159+FM196 -> 4.999092 | FN11: =FN48+FN85+FN122+FN159+FN196 -> 1.666364 | FO11: =FO48+FO85+FO122+FO159+FO196 -> 1.666364 | ... GQ11: =GQ48+GQ85+GQ122+GQ159+GQ196 -> 0 | GS11: 4 | GT11: CP03-04 | GU11: Internet | GV11: =GV48+GV85+GV122+GV159+GV196 -> 3.7487863 | GW11: =GW48+GW85+GW122+GW159+GW196 -> 14.723756 | GX11: =GX48+GX85+GX122+GX159+GX196 -> 1.407869 | GY11: =GY48+GY85+GY122+GY159+GY196 -> 1.528181 | GZ11: =GZ48+GZ85+GZ122+GZ159+GZ196 -> 1.528181 | HA11: =HA48+HA85+HA122+HA159+HA196 -> 4.464231 | HB11: =HB48+HB85+HB122+HB159+HB196 -> 1.528181 | HC11: =HC48+HC85+HC122+HC159+HC196 -> 2.5 | ... IE11: =IE48+IE85+IE122+IE159+IE196 -> 1.675908
A12: 5 | B12: CP03-05 | C12: Nước sinh hoạt | D12: =D49+D86+D123+D160+D197 -> 40.965314 | E12: =E49+E86+E123+E160+E197 -> 113.41515 | F12: =F49+F86+F123+F160+F197 -> 15.098554 | G12: =G49+G86+G123+G160+G197 -> 21.487363 | H12: =H49+H86+H123+H160+H197 -> 18.796867 | I12: =I49+I86+I123+I160+I197 -> 55.382784 | J12: =J49+J86+J123+J160+J197 -> 22.40295 | K12: =K49+K86+K123+K160+K197 -> 17.734769 | ... AM12: =AM49+AM86+AM123+AM160+AM197 -> 3.786435 | AO12: 5 | AP12: CP03-05 | AQ12: Nước sinh hoạt | AR12: =AR49+AR86+AR123+AR160+AR197 -> 27.692209 | AS12: =AS49+AS86+AS123+AS160+AS197 -> 53.848734 | AT12: =AT49+AT86+AT123+AT160+AT197 -> 8.2216869 | AU12: =AU49+AU86+AU123+AU160+AU197 -> 14.821515 | AV12: =AV49+AV86+AV123+AV160+AV197 -> 12.565876 | AW12: =AW49+AW86+AW123+AW160+AW197 -> 35.609078 | AX12: =AX49+AX86+AX123+AX160+AX197 -> 18.810096 | AY12: =AY49+AY86+AY123+AY160+AY197 -> 13.968381 | ... CA12: =CA49+CA86+CA123+CA160+CA197 -> 0 | CC12: 5 | CD12: CP03-05 | CE12: Nước sinh hoạt | CF12: ='1.Danh muc CPHC'!CF49+'1.Danh muc CPHC'!CF86+'1.Danh muc CPHC'!CF123+'1.Danh muc CPHC'!CF160+'1.Danh muc CPHC'!CF197 -> 3.2131823 | CG12: ='1.Danh muc CPHC'!CG49+'1.Danh muc CPHC'!CG86+'1.Danh muc CPHC'!CG123+'1.Danh muc CPHC'!CG160+'1.Danh muc CPHC'!CG197 -> 6.5579309 | CH12: ='1.Danh muc CPHC'!CH49+'1.Danh muc CPHC'!CH86+'1.Danh muc CPHC'!CH123+'1.Danh muc CPHC'!CH160+'1.Danh muc CPHC'!CH197 -> 1.9365897 | CI12: ='1.Danh muc CPHC'!CI49+'1.Danh muc CPHC'!CI86+'1.Danh muc CPHC'!CI123+'1.Danh muc CPHC'!CI160+'1.Danh muc CPHC'!CI197 -> 3.1819606 | CJ12: ='1.Danh muc CPHC'!CJ49+'1.Danh muc CPHC'!CJ86+'1.Danh muc CPHC'!CJ123+'1.Danh muc CPHC'!CJ160+'1.Danh muc CPHC'!CJ197 -> 2.7279696 | CK12: ='1.Danh muc CPHC'!CK49+'1.Danh muc CPHC'!CK86+'1.Danh muc CPHC'!CK123+'1.Danh muc CPHC'!CK160+'1.Danh muc CPHC'!CK197 -> 7.8465199 | CL12: =CL49+CL86+CL123+CL160+CL197 -> 0 | CM12: =CM49+CM86+CM123+CM160+CM197 -> 0 | CN12: =CN49+CN86+CN123+CN160+CN197 -> 0 | CO12: =CO49+CO86+CO123+CO160+CO197 -> 0 | CP12: =CP49+CP86+CP123+CP160+CP197 -> 0 | CQ12: =CQ49+CQ86+CQ123+CQ160+CQ197 -> 0 | CR12: =CR49+CR86+CR123+CR160+CR197 -> 0 | CS12: =CS49+CS86+CS123+CS160+CS197 -> 0 | ... CX12: =CX49+CX86+CX123+CX160+CX197 -> 7.8465199 | DQ12: 5 | DR12: CP03-05 | DS12: Nước sinh hoạt | DT12: =DT49+DT86+DT123+DT160+DT197 -> 3.025402 | DU12: =DU49+DU86+DU123+DU160+DU197 -> 12.265285 | DV12: =DV49+DV86+DV123+DV160+DV197 -> 1.288229 | DW12: =DW49+DW86+DW123+DW160+DW197 -> 1.23915 | DX12: =DX49+DX86+DX123+DX160+DX197 -> 1.055001 | DY12: =DY49+DY86+DY123+DY160+DY197 -> 3.58238 | DZ12: =DZ49+DZ86+DZ123+DZ160+DZ197 -> 1.23823 | EA12: =EA49+EA86+EA123+EA160+EA197 -> 1.731644 | ... EP12: =EP49+EP86+EP123+EP160+EP197 -> 0 | FE12: 5 | FF12: CP03-05 | FG12: Nước sinh hoạt | FH12: =FH49+FH86+FH123+FH160+FH197 -> 2.60174 | FI12: =FI49+FI86+FI123+FI160+FI197 -> 14.253775 | FJ12: =FJ49+FJ86+FJ123+FJ160+FJ197 -> 2.199999 | FK12: =FK49+FK86+FK123+FK160+FK197 -> 0.707826 | FL12: =FL49+FL86+FL123+FL160+FL197 -> 1.11913 | FM12: =FM49+FM86+FM123+FM160+FM197 -> 4.026955 | FN12: =FN49+FN86+FN123+FN160+FN197 -> 1.042609 | FO12: =FO49+FO86+FO123+FO160+FO197 -> 1.013914 | ... GQ12: =GQ49+GQ86+GQ123+GQ160+GQ197 -> 0 | GS12: 5 | GT12: CP03-05 | GU12: Nước sinh hoạt | GV12: =GV49+GV86+GV123+GV160+GV197 -> 4.4327805 | GW12: =GW49+GW86+GW123+GW160+GW197 -> 26.489425 | GX12: =GX49+GX86+GX123+GX160+GX197 -> 1.452049 | GY12: =GY49+GY86+GY123+GY160+GY197 -> 1.536912 | GZ12: =GZ49+GZ86+GZ123+GZ160+GZ197 -> 1.32889 | HA12: =HA49+HA86+HA123+HA160+HA197 -> 4.317851 | HB12: =HB49+HB86+HB123+HB160+HB197 -> 1.312015 | HC12: =HC49+HC86+HC123+HC160+HC197 -> 1.02083 | ... IE12: =IE49+IE86+IE123+IE160+IE197 -> 3.786435
A13: 6 | B13: CP03-06 | C13: Nước uống | D13: =D50+D87+D124+D161+D198 -> 14.596926 | E13: =E50+E87+E124+E161+E198 -> 65.722746 | F13: =F50+F87+F124+F161+F198 -> 4.3186552 | G13: =G50+G87+G124+G161+G198 -> 4.2044725 | H13: =H50+H87+H124+H161+H198 -> 4.6929692 | I13: =I50+I87+I124+I161+I198 -> 13.216097 | J13: =J50+J87+J124+J161+J198 -> 4.218103 | K13: =K50+K87+K124+K161+K198 -> 3.292073 | ... AM13: =AM50+AM87+AM124+AM161+AM198 -> 0.984 | AO13: 6 | AP13: CP03-06 | AQ13: Nước uống | AR13: =AR50+AR87+AR124+AR161+AR198 -> 5.7532873 | AS13: =AS50+AS87+AS124+AS161+AS198 -> 22.991039 | AT13: =AT50+AT87+AT124+AT161+AT198 -> 2.1078916 | AU13: =AU50+AU87+AU124+AU161+AU198 -> 1.8766055 | AV13: =AV50+AV87+AV124+AV161+AV198 -> 2.2270489 | AW13: =AW50+AW87+AW124+AW161+AW198 -> 6.211546 | AX13: =AX50+AX87+AX124+AX161+AX198 -> 2.365683 | AY13: =AY50+AY87+AY124+AY161+AY198 -> 1.394085 | ... CA13: =CA50+CA87+CA124+CA161+CA198 -> 0 | CC13: 6 | CD13: CP03-06 | CE13: Nước uống | CF13: ='1.Danh muc CPHC'!CF50+'1.Danh muc CPHC'!CF87+'1.Danh muc CPHC'!CF124+'1.Danh muc CPHC'!CF161+'1.Danh muc CPHC'!CF198 -> 0.78454546 | CG13: ='1.Danh muc CPHC'!CG50+'1.Danh muc CPHC'!CG87+'1.Danh muc CPHC'!CG124+'1.Danh muc CPHC'!CG161+'1.Danh muc CPHC'!CG198 -> 6.9991013 | CH13: ='1.Danh muc CPHC'!CH50+'1.Danh muc CPHC'!CH87+'1.Danh muc CPHC'!CH124+'1.Danh muc CPHC'!CH161+'1.Danh muc CPHC'!CH198 -> 0.51208352 | CI13: ='1.Danh muc CPHC'!CI50+'1.Danh muc CPHC'!CI87+'1.Danh muc CPHC'!CI124+'1.Danh muc CPHC'!CI161+'1.Danh muc CPHC'!CI198 -> 0.42970708 | CJ13: ='1.Danh muc CPHC'!CJ50+'1.Danh muc CPHC'!CJ87+'1.Danh muc CPHC'!CJ124+'1.Danh muc CPHC'!CJ161+'1.Danh muc CPHC'!CJ198 -> 0.52365624 | CK13: ='1.Danh muc CPHC'!CK50+'1.Danh muc CPHC'!CK87+'1.Danh muc CPHC'!CK124+'1.Danh muc CPHC'!CK161+'1.Danh muc CPHC'!CK198 -> 1.4654468 | CL13: =CL50+CL87+CL124+CL161+CL198 -> 0 | CM13: =CM50+CM87+CM124+CM161+CM198 -> 0 | CN13: =CN50+CN87+CN124+CN161+CN198 -> 0 | CO13: =CO50+CO87+CO124+CO161+CO198 -> 0 | CP13: =CP50+CP87+CP124+CP161+CP198 -> 0 | CQ13: =CQ50+CQ87+CQ124+CQ161+CQ198 -> 0 | CR13: =CR50+CR87+CR124+CR161+CR198 -> 0 | CS13: =CS50+CS87+CS124+CS161+CS198 -> 0 | ... CX13: =CX50+CX87+CX124+CX161+CX198 -> 1.4654468 | DQ13: 6 | DR13: CP03-06 | DS13: Nước uống | DT13: =DT50+DT87+DT124+DT161+DT198 -> 0.9 | DU13: =DU50+DU87+DU124+DU161+DU198 -> 6 | DV13: =DV50+DV87+DV124+DV161+DV198 -> 0.400032 | DW13: =DW50+DW87+DW124+DW161+DW198 -> 0.400032 | DX13: =DX50+DX87+DX124+DX161+DX198 -> 0.400032 | DY13: =DY50+DY87+DY124+DY161+DY198 -> 1.200096 | DZ13: =DZ50+DZ87+DZ124+DZ161+DZ198 -> 0.400032 | EA13: =EA50+EA87+EA124+EA161+EA198 -> 0.377808 | ... EP13: =EP50+EP87+EP124+EP161+EP198 -> 0 | FE13: 6 | FF13: CP03-06 | FG13: Nước uống | FH13: =FH50+FH87+FH124+FH161+FH198 -> 5.031925 | FI13: =FI50+FI87+FI124+FI161+FI198 -> 20.024606 | FJ13: =FJ50+FJ87+FJ124+FJ161+FJ198 -> 0.674648 | FK13: =FK50+FK87+FK124+FK161+FK198 -> 0.934128 | FL13: =FL50+FL87+FL124+FL161+FL198 -> 0.882232 | FM13: =FM50+FM87+FM124+FM161+FM198 -> 2.491008 | FN13: =FN50+FN87+FN124+FN161+FN198 -> 0.804388 | FO13: =FO50+FO87+FO124+FO161+FO198 -> 0.90818 | ... GQ13: =GQ50+GQ87+GQ124+GQ161+GQ198 -> 0 | GS13: 6 | GT13: CP03-06 | GU13: Nước uống | GV13: =GV50+GV87+GV124+GV161+GV198 -> 2.127168 | GW13: =GW50+GW87+GW124+GW161+GW198 -> 9.708 | GX13: =GX50+GX87+GX124+GX161+GX198 -> 0.624 | GY13: =GY50+GY87+GY124+GY161+GY198 -> 0.564 | GZ13: =GZ50+GZ87+GZ124+GZ161+GZ198 -> 0.66 | HA13: =HA50+HA87+HA124+HA161+HA198 -> 1.848 | HB13: =HB50+HB87+HB124+HB161+HB198 -> 0.648 | HC13: =HC50+HC87+HC124+HC161+HC198 -> 0.612 | ... IE13: =IE50+IE87+IE124+IE161+IE198 -> 0.984
A14: 7 | B14: CP03-07 | C14: Chi phí xử lý chất thải (nước thải, rác), phí vệ sinh | D14: =D51+D88+D125+D162+D199 -> 57.679857 | E14: =E51+E88+E125+E162+E199 -> 305.3446 | F14: =F51+F88+F125+F162+F199 -> 19.058199 | G14: =G51+G88+G125+G162+G199 -> 25.618527 | H14: =H51+H88+H125+H162+H199 -> 15.375558 | I14: =I51+I88+I125+I162+I199 -> 60.052284 | J14: =J51+J88+J125+J162+J199 -> 13.006443 | K14: =K51+K88+K125+K162+K199 -> 14.216337 | ... AM14: =AM51+AM88+AM125+AM162+AM199 -> 18.774134 | AO14: 7 | AP14: CP03-07 | AQ14: Chi phí xử lý chất thải (nước thải, rác), phí vệ sinh | AR14: =AR51+AR88+AR125+AR162+AR199 -> 26.890678 | AS14: =AS51+AS88+AS125+AS162+AS199 -> 196.6189 | AT14: =AT51+AT88+AT125+AT162+AT199 -> 11.497477 | AU14: =AU51+AU88+AU125+AU162+AU199 -> 7.3904933 | AV14: =AV51+AV88+AV125+AV162+AV199 -> 9.3684924 | AW14: =AW51+AW88+AW125+AW162+AW199 -> 28.256463 | AX14: =AX51+AX88+AX125+AX162+AX199 -> 7.865052 | AY14: =AY51+AY88+AY125+AY162+AY199 -> 9.251015 | ... CA14: =CA51+CA88+CA125+CA162+CA199 -> 0 | CC14: 7 | CD14: CP03-07 | CE14: Chi phí xử lý chất thải (nước thải, rác), phí vệ sinh | CF14: ='1.Danh muc CPHC'!CF51+'1.Danh muc CPHC'!CF88+'1.Danh muc CPHC'!CF125+'1.Danh muc CPHC'!CF162+'1.Danh muc CPHC'!CF199 -> 2.7578531 | CG14: ='1.Danh muc CPHC'!CG51+'1.Danh muc CPHC'!CG88+'1.Danh muc CPHC'!CG125+'1.Danh muc CPHC'!CG162+'1.Danh muc CPHC'!CG199 -> 6.64 | CH14: ='1.Danh muc CPHC'!CH51+'1.Danh muc CPHC'!CH88+'1.Danh muc CPHC'!CH125+'1.Danh muc CPHC'!CH162+'1.Danh muc CPHC'!CH199 -> 1.3865504 | CI14: ='1.Danh muc CPHC'!CI51+'1.Danh muc CPHC'!CI88+'1.Danh muc CPHC'!CI125+'1.Danh muc CPHC'!CI162+'1.Danh muc CPHC'!CI199 -> 1.4378874 | CJ14: ='1.Danh muc CPHC'!CJ51+'1.Danh muc CPHC'!CJ88+'1.Danh muc CPHC'!CJ125+'1.Danh muc CPHC'!CJ162+'1.Danh muc CPHC'!CJ199 -> 1.7138872 | CK14: ='1.Danh muc CPHC'!CK51+'1.Danh muc CPHC'!CK88+'1.Danh muc CPHC'!CK125+'1.Danh muc CPHC'!CK162+'1.Danh muc CPHC'!CK199 -> 4.538325 | CL14: =CL51+CL88+CL125+CL162+CL199 -> 0 | CM14: =CM51+CM88+CM125+CM162+CM199 -> 0 | CN14: =CN51+CN88+CN125+CN162+CN199 -> 0 | CO14: =CO51+CO88+CO125+CO162+CO199 -> 0 | CP14: =CP51+CP88+CP125+CP162+CP199 -> 0 | CQ14: =CQ51+CQ88+CQ125+CQ162+CQ199 -> 0 | CR14: =CR51+CR88+CR125+CR162+CR199 -> 0 | CS14: =CS51+CS88+CS125+CS162+CS199 -> 0 | ... CX14: =CX51+CX88+CX125+CX162+CX199 -> 4.538325 | DQ14: 7 | DR14: CP03-07 | DS14: Chi phí xử lý chất thải (nước thải, rác), phí vệ sinh | DT14: =DT51+DT88+DT125+DT162+DT199 -> 9.290679 | DU14: =DU51+DU88+DU125+DU162+DU199 -> 20.392154 | DV14: =DV51+DV88+DV125+DV162+DV199 -> 2.325393 | DW14: =DW51+DW88+DW125+DW162+DW199 -> 10.362393 | DX14: =DX51+DX88+DX125+DX162+DX199 -> 0.680393 | DY14: =DY51+DY88+DY125+DY162+DY199 -> 13.368179 | DZ14: =DZ51+DZ88+DZ125+DZ162+DZ199 -> 0.680393 | EA14: =EA51+EA88+EA125+EA162+EA199 -> 0.680393 | ... EP14: =EP51+EP88+EP125+EP162+EP199 -> 0 | FE14: 7 | FF14: CP03-07 | FG14: Chi phí xử lý chất thải (nước thải, rác), phí vệ sinh | FH14: =FH51+FH88+FH125+FH162+FH199 -> 10.484358 | FI14: =FI51+FI88+FI125+FI162+FI199 -> 42.623872 | FJ14: =FJ51+FJ88+FJ125+FJ162+FJ199 -> 1.074546 | FK14: =FK51+FK88+FK125+FK162+FK199 -> 2.992827 | FL14: =FL51+FL88+FL125+FL162+FL199 -> 1.123258 | FM14: =FM51+FM88+FM125+FM162+FM199 -> 5.190631 | FN14: =FN51+FN88+FN125+FN162+FN199 -> 2.158605 | FO14: =FO51+FO88+FO125+FO162+FO199 -> 1.345336 | ... GQ14: =GQ51+GQ88+GQ125+GQ162+GQ199 -> 0 | GS14: 7 | GT14: CP03-07 | GU14: Chi phí xử lý chất thải (nước thải, rác), phí vệ sinh | GV14: =GV51+GV88+GV125+GV162+GV199 -> 8.2562894 | GW14: =GW51+GW88+GW125+GW162+GW199 -> 39.069665 | GX14: =GX51+GX88+GX125+GX162+GX199 -> 2.774233 | GY14: =GY51+GY88+GY125+GY162+GY199 -> 3.434926 | GZ14: =GZ51+GZ88+GZ125+GZ162+GZ199 -> 2.489527 | HA14: =HA51+HA88+HA125+HA162+HA199 -> 8.698686 | HB14: =HB51+HB88+HB125+HB162+HB199 -> 2.302393 | HC14: =HC51+HC88+HC125+HC162+HC199 -> 2.939593 | ... IE14: =IE51+IE88+IE125+IE162+IE199 -> 18.774134
